Exception in thread django-main-thread:
Traceback (most recent call last):
  File "/usr/lib/python3.11/threading.py", line 1038, in _bootstrap_inner
    self.run()
  File "/usr/lib/python3.11/threading.py", line 975, in run
    self._target(*self._args, **self._kwargs)
  File "/home/clta/Documents/SAE301-RBAC-check/SAE301-main-inspect/SAE301-main/PythonProject/PythonProject/venv/lib/python3.11/site-packages/django/utils/autoreload.py", line 64, in wrapper
    fn(*args, **kwargs)
  File "/home/clta/Documents/SAE301-RBAC-check/SAE301-main-inspect/SAE301-main/PythonProject/PythonProject/venv/lib/python3.11/site-packages/django/core/management/commands/runserver.py", line 134, in inner_run
    self.check(**check_kwargs)
  File "/home/clta/Documents/SAE301-RBAC-check/SAE301-main-inspect/SAE301-main/PythonProject/PythonProject/venv/lib/python3.11/site-packages/django/core/management/base.py", line 492, in check
    all_issues = checks.run_checks(
                 ^^^^^^^^^^^^^^^^^^
  File "/home/clta/Documents/SAE301-RBAC-check/SAE301-main-inspect/SAE301-main/PythonProject/PythonProject/venv/lib/python3.11/site-packages/django/core/checks/registry.py", line 89, in run_checks
    new_errors = check(app_configs=app_configs, databases=databases)
                 ^^^^^^^^^^^^^^^^^^^^^^^^^^^^^^^^^^^^^^^^^^^^^^^^^^^
  File "/home/clta/Documents/SAE301-RBAC-check/SAE301-main-inspect/SAE301-main/PythonProject/PythonProject/venv/lib/python3.11/site-packages/django/core/checks/urls.py", line 16, in check_url_config
    return check_resolver(resolver)
           ^^^^^^^^^^^^^^^^^^^^^^^^
  File "/home/clta/Documents/SAE301-RBAC-check/SAE301-main-inspect/SAE301-main/PythonProject/PythonProject/venv/lib/python3.11/site-packages/django/core/checks/urls.py", line 26, in check_resolver
    return check_method()
           ^^^^^^^^^^^^^^
  File "/home/clta/Documents/SAE301-RBAC-check/SAE301-main-inspect/SAE301-main/PythonProject/PythonProject/venv/lib/python3.11/site-packages/django/urls/resolvers.py", line 531, in check
    for pattern in self.url_patterns:
                   ^^^^^^^^^^^^^^^^^
  File "/home/clta/Documents/SAE301-RBAC-check/SAE301-main-inspect/SAE301-main/PythonProject/PythonProject/venv/lib/python3.11/site-packages/django/utils/functional.py", line 47, in __get__
    res = instance.__dict__[self.name] = self.func(instance)
                                         ^^^^^^^^^^^^^^^^^^^
  File "/home/clta/Documents/SAE301-RBAC-check/SAE301-main-inspect/SAE301-main/PythonProject/PythonProject/venv/lib/python3.11/site-packages/django/urls/resolvers.py", line 718, in url_patterns
    patterns = getattr(self.urlconf_module, "urlpatterns", self.urlconf_module)
                       ^^^^^^^^^^^^^^^^^^^
  File "/home/clta/Documents/SAE301-RBAC-check/SAE301-main-inspect/SAE301-main/PythonProject/PythonProject/venv/lib/python3.11/site-packages/django/utils/functional.py", line 47, in __get__
    res = instance.__dict__[self.name] = self.func(instance)
                                         ^^^^^^^^^^^^^^^^^^^
  File "/home/clta/Documents/SAE301-RBAC-check/SAE301-main-inspect/SAE301-main/PythonProject/PythonProject/venv/lib/python3.11/site-packages/django/urls/resolvers.py", line 711, in urlconf_module
    return import_module(self.urlconf_name)
           ^^^^^^^^^^^^^^^^^^^^^^^^^^^^^^^^
  File "/usr/lib/python3.11/importlib/__init__.py", line 126, in import_module
    return _bootstrap._gcd_import(name[level:], package, level)
           ^^^^^^^^^^^^^^^^^^^^^^^^^^^^^^^^^^^^^^^^^^^^^^^^^^^^
  File "<frozen importlib._bootstrap>", line 1206, in _gcd_import
  File "<frozen importlib._bootstrap>", line 1178, in _find_and_load
  File "<frozen importlib._bootstrap>", line 1149, in _find_and_load_unlocked
  File "<frozen importlib._bootstrap>", line 690, in _load_unlocked
  File "<frozen importlib._bootstrap_external>", line 940, in exec_module
  File "<frozen importlib._bootstrap>", line 241, in _call_with_frames_removed
  File "/home/clta/Documents/SAE301-RBAC-check/SAE301-main-inspect/SAE301-main/PythonProject/PythonProject/Serv_web/Serv_web/urls.py", line 22, in <module>
    path('', include('prises.urls')),
             ^^^^^^^^^^^^^^^^^^^^^^
  File "/home/clta/Documents/SAE301-RBAC-check/SAE301-main-inspect/SAE301-main/PythonProject/PythonProject/venv/lib/python3.11/site-packages/django/urls/conf.py", line 39, in include
    urlconf_module = import_module(urlconf_module)
                     ^^^^^^^^^^^^^^^^^^^^^^^^^^^^^
  File "/usr/lib/python3.11/importlib/__init__.py", line 126, in import_module
    return _bootstrap._gcd_import(name[level:], package, level)
           ^^^^^^^^^^^^^^^^^^^^^^^^^^^^^^^^^^^^^^^^^^^^^^^^^^^^
  File "<frozen importlib._bootstrap>", line 1206, in _gcd_import
  File "<frozen importlib._bootstrap>", line 1178, in _find_and_load
  File "<frozen importlib._bootstrap>", line 1149, in _find_and_load_unlocked
  File "<frozen importlib._bootstrap>", line 690, in _load_unlocked
  File "<frozen importlib._bootstrap_external>", line 940, in exec_module
  File "<frozen importlib._bootstrap>", line 241, in _call_with_frames_removed
  File "/home/clta/Documents/SAE301-RBAC-check/SAE301-main-inspect/SAE301-main/PythonProject/PythonProject/Serv_web/prises/urls.py", line 2, in <module>
    from . import views
  File "/home/clta/Documents/SAE301-RBAC-check/SAE301-main-inspect/SAE301-main/PythonProject/PythonProject/Serv_web/prises/views.py", line 64, in <module>
    @user_passes_test(is_controle)
                      ^^^^^^^^^^^
NameError: name 'is_controle' is not defined
